Workbook

Sheet 응답데이터
A1: AHP 설문 응답 데이터 입력
A2: CSV 파일의 데이터를 아래에 붙여넣으세요. 각 행이 한 명의 응답자입니다. 노란색 셀에 쌍대비교값을 입력합니다. (왼쪽 중요: 1~9, 오른쪽 중요: 1/3~1/9)
A3: 응답자 일반사항 | J3: 제1계층: 핵심가치 간 비교 (15쌍) | Y3: 자립성 (3쌍) | AB3: 연계성 (3쌍) | AE3: 실용성 (3쌍) | AH3: 포용성 (3쌍) | AK3: 지속가능성 (3쌍) | AN3: 확장성 (3쌍)
A4: 응답자 | B4: 응답일시 | C4: 소속유형 | D4: 소속기관 | E4: 직위 | F4: 관심분야 | G4: 경력 | H4: 성별 | I4: 연락처 | J4: 자립성 vs 연계성 | K4: 자립성 vs 실용성 | L4: 자립성 vs 포용성 | M4: 자립성 vs 지속가능성 | N4: 자립성 vs 확장성 | O4: 연계성 vs 실용성 | P4: 연계성 vs 포용성 | Q4: 연계성 vs 지속가능성 | R4: 연계성 vs 확장성 | S4: 실용성 vs 포용성 | T4: 실용성 vs 지속가능성 | U4: 실용성 vs 확장성 | V4: 포용성 vs 지속가능성 | W4: 포용성 vs 확장성 | X4: 지속가능성 vs 확장성 | Y4: [자립성] 지역 R&D 역량 강화 vs 지역기업 기술흡수역량 강화 | Z4: [자립성] 지역 R&D 역량 강화 vs 지역혁신 인재양성 | AA4: [자립성] 지역기업 기술흡수역량 강화 vs 지역혁신 인재양성 | AB4: [연계성] 산·학·연·관 협력 강화 vs 기업 간 네트워크 활성화 | AC4: [연계성] 산·학·연·관 협력 강화 vs 중간지원기관 조정 기능 강화 | AD4: [연계성] 기업 간 네트워크 활성화 vs 중간지원기관 조정 기능 강화 | AE4: [실용성] 기술사업화 지원 vs 기업 기술애로 해결 | AF4: [실용성] 기술사업화 지원 vs 매출·고용 창출 연계 | AG4: [실용성] 기업 기술애로 해결 vs 매출·고용 창출 연계 | AH4: [포용성] 중소기업 정책 접근성 강화 vs 청년·창업기업 참여 확대 | AI4: [포용성] 중소기업 정책 접근성 강화 vs 지역대학 및 지역사회 참여 확대 | AJ4: [포용성] 청년·창업기업 참여 확대 vs 지역대학 및 지역사회 참여 확대 | AK4: [지속가능성] 정책 연속성 확보 vs 혁신거버넌스 안정화 | AL4: [지속가능성] 정책 연속성 확보 vs 혁신인프라 유지·고도화 | AM4: [지속가능성] 혁신거버넌스 안정화 vs 혁신인프라 유지·고도화 | AN4: [확장성] 외부 지식·기술 연계 vs 글로벌 시장 진출 지원 | AO4: [확장성] 외부 지식·기술 연계 vs 신산업 전환 및 확산 | AP4: [확장성] 글로벌 시장 진출 지원 vs 신산업 전환 및 확산
A5: 응답자1 | B5: 2026-05-18 10:00 | C5: 대학 및 출연연 | D5: 단국대학교 | E5: 연구자/교수 | F5: 지역혁신정책;연구개발 | G5: 15년 이상 | H5: 남성 | I5: 010-1234-5678 | J5: 3 | K5: 5 | L5: 7 | M5: 3 | N5: 5 | O5: 3 | P5: 5 | Q5: 1 | R5: 3 | S5: 3 | T5: 0.3333 | U5: 1 | V5: 0.3333 | W5: 0.3333 | X5: 1 | Y5: 3 | Z5: 5 | AA5: 3 | AB5: 3 | AC5: 5 | AD5: 3 | AE5: 1 | AF5: 3 | AG5: 3 | AH5: 3 | AI5: 1 | AJ5: 0.3333 | AK5: 3 | AL5: 5 | AM5: 3 | AN5: 0.3333 | AO5: 1 | AP5: 3
A6: 응답자2 | B6: 2026-05-18 11:00 | C6: 기업 | D6: 삼성전자 | E6: 관리자 | F6: 기업지원;기술사업화 | G6: 10~15년 | H6: 남성 | I6: 010-2345-6789 | J6: 0.3333 | K6: 0.2 | L6: 3 | M6: 0.3333 | N6: 1 | O6: 0.3333 | P6: 3 | Q6: 1 | R6: 3 | S6: 5 | T6: 3 | U6: 3 | V6: 0.3333 | W6: 0.3333 | X6: 1 | Y6: 1 | Z6: 3 | AA6: 3 | AB6: 1 | AC6: 3 | AD6: 3 | AE6: 3 | AF6: 5 | AG6: 3 | AH6: 1 | AI6: 3 | AJ6: 3 | AK6: 1 | AL6: 3 | AM6: 3 | AN6: 0.3333 | AO6: 3 | AP6: 5
A7: 응답자3 | B7: 2026-05-18 14:00 | C7: 정부(공공기관) | D7: 충남테크노파크 | E7: 실무자 | F7: 산학협력;산업정책 | G7: 5~10년 | H7: 여성 | I7: 010-3456-7890 | J7: 1 | K7: 3 | L7: 3 | M7: 1 | N7: 3 | O7: 3 | P7: 3 | Q7: 1 | R7: 3 | S7: 1 | T7: 0.3333 | U7: 1 | V7: 0.3333 | W7: 0.3333 | X7: 1 | Y7: 1 | Z7: 1 | AA7: 1 | AB7: 1 | AC7: 1 | AD7: 1 | AE7: 1 | AF7: 1 | AG7: 1 | AH7: 1 | AI7: 1 | AJ7: 1 | AK7: 1 | AL7: 1 | AM7: 1 | AN7: 1 | AO7: 1 | AP7: 1
A8: 응답자4
A9: 응답자5
A10: 응답자6
A11: 응답자7
A12: 응답자8
A13: 응답자9
A14: 응답자10
A15: 응답자11
A16: 응답자12
A17: 응답자13
A18: 응답자14
A19: 응답자15
... A34: 응답자30
A36: 기하평균 | J36: =IF(COUNT(J5:J34)=0,1,GEOMEAN(J5:J34)) | K36: =IF(COUNT(K5:K34)=0,1,GEOMEAN(K5:K34)) | L36: =IF(COUNT(L5:L34)=0,1,GEOMEAN(L5:L34)) | M36: =IF(COUNT(M5:M34)=0,1,GEOMEAN(M5:M34)) | N36: =IF(COUNT(N5:N34)=0,1,GEOMEAN(N5:N34)) | O36: =IF(COUNT(O5:O34)=0,1,GEOMEAN(O5:O34)) | P36: =IF(COUNT(P5:P34)=0,1,GEOMEAN(P5:P34)) | Q36: =IF(COUNT(Q5:Q34)=0,1,GEOMEAN(Q5:Q34)) | ... AP36: =IF(COUNT(AP5:AP34)=0,1,GEOMEAN(AP5:AP34))
A37: 응답수 | J37: =COUNT(J5:J34) | K37: =COUNT(K5:K34) | L37: =COUNT(L5:L34) | M37: =COUNT(M5:M34) | N37: =COUNT(N5:N34) | O37: =COUNT(O5:O34) | P37: =COUNT(P5:P34) | Q37: =COUNT(Q5:Q34) | ... AP37: =COUNT(AP5:AP34)

Sheet AHP분석결과
A1: AHP 분석 결과 (자동 계산)
A2: 응답데이터 시트의 기하평균을 기반으로 자동 계산됩니다.
A4: 제1계층: 핵심가치 가중치 분석
A5: [쌍대비교행렬 (기하평균)]
B6: 자립성 | C6: 연계성 | D6: 실용성 | E6: 포용성 | F6: 지속가능성 | G6: 확장성
A7: 자립성 | B7: 1 | C7: ='응답데이터'!J36 | D7: ='응답데이터'!K36 | E7: ='응답데이터'!L36 | F7: ='응답데이터'!M36 | G7: ='응답데이터'!N36
A8: 연계성 | B8: =1/C7 | C8: 1 | D8: ='응답데이터'!O36 | E8: ='응답데이터'!P36 | F8: ='응답데이터'!Q36 | G8: ='응답데이터'!R36
A9: 실용성 | B9: =1/D7 | C9: =1/D8 | D9: 1 | E9: ='응답데이터'!S36 | F9: ='응답데이터'!T36 | G9: ='응답데이터'!U36
A10: 포용성 | B10: =1/E7 | C10: =1/E8 | D10: =1/E9 | E10: 1 | F10: ='응답데이터'!V36 | G10: ='응답데이터'!W36
A11: 지속가능성 | B11: =1/F7 | C11: =1/F8 | D11: =1/F9 | E11: =1/F10 | F11: 1 | G11: ='응답데이터'!X36
A12: 확장성 | B12: =1/G7 | C12: =1/G8 | D12: =1/G9 | E12: =1/G10 | F12: =1/G11 | G12: 1
A13: 열 합계 | B13: =SUM(B7:B12) | C13: =SUM(C7:C12) | D13: =SUM(D7:D12) | E13: =SUM(E7:E12) | F13: =SUM(F7:F12) | G13: =SUM(G7:G12)
A15: [정규화행렬 및 가중치]
B16: 자립성 | C16: 연계성 | D16: 실용성 | E16: 포용성 | F16: 지속가능성 | G16: 확장성 | H16: 가중치(Wi)
A17: 자립성 | B17: =B7/B13 | C17: =C7/C13 | D17: =D7/D13 | E17: =E7/E13 | F17: =F7/F13 | G17: =G7/G13 | H17: =AVERAGE(B17:G17)
A18: 연계성 | B18: =B8/B13 | C18: =C8/C13 | D18: =D8/D13 | E18: =E8/E13 | F18: =F8/F13 | G18: =G8/G13 | H18: =AVERAGE(B18:G18)
A19: 실용성 | B19: =B9/B13 | C19: =C9/C13 | D19: =D9/D13 | E19: =E9/E13 | F19: =F9/F13 | G19: =G9/G13 | H19: =AVERAGE(B19:G19)
A20: 포용성 | B20: =B10/B13 | C20: =C10/C13 | D20: =D10/D13 | E20: =E10/E13 | F20: =F10/F13 | G20: =G10/G13 | H20: =AVERAGE(B20:G20)
A21: 지속가능성 | B21: =B11/B13 | C21: =C11/C13 | D21: =D11/D13 | E21: =E11/E13 | F21: =F11/F13 | G21: =G11/G13 | H21: =AVERAGE(B21:G21)
A22: 확장성 | B22: =B12/B13 | C22: =C12/C13 | D22: =D12/D13 | E22: =E12/E13 | F22: =F12/F13 | G22: =G12/G13 | H22: =AVERAGE(B22:G22)
A24: [일관성 검증]
A25: 항목 | B25: 가중치(Wi) | C25: 가중합(Aw) | D25: Aw/Wi
A26: 자립성 | B26: =H17 | C26: =B7*H17+C7*H18+D7*H19+E7*H20+F7*H21+G7*H22 | D26: =C26/B26
A27: 연계성 | B27: =H18 | C27: =B8*H17+C8*H18+D8*H19+E8*H20+F8*H21+G8*H22 | D27: =C27/B27
A28: 실용성 | B28: =H19 | C28: =B9*H17+C9*H18+D9*H19+E9*H20+F9*H21+G9*H22 | D28: =C28/B28
A29: 포용성 | B29: =H20 | C29: =B10*H17+C10*H18+D10*H19+E10*H20+F10*H21+G10*H22 | D29: =C29/B29
A30: 지속가능성 | B30: =H21 | C30: =B11*H17+C11*H18+D11*H19+E11*H20+F11*H21+G11*H22 | D30: =C30/B30
A31: 확장성 | B31: =H22 | C31: =B12*H17+C12*H18+D12*H19+E12*H20+F12*H21+G12*H22 | D31: =C31/B31
A33: λmax | B33: =AVERAGE(D26,D27,D28,D29,D30,D31)
A34: CI | B34: =(B33-6)/(6-1)
A35: RI | B35: 1.24
A36: CR | B36: =B34/1.24
A37: 판정결과 | B37: =IF(B36<=0.1,"PASS (CR<=0.1, 적합)","FAIL (CR>0.1, 부적합 - 재설문 필요)")
A39: 제2계층: 자립성 - 정책요인 가중치 분석
A40: [쌍대비교행렬 (기하평균)]
B41: 지역 R&D 역량 강화 | C41: 지역기업 기술흡수역량 강화 | D41: 지역혁신 인재양성
A42: 지역 R&D 역량 강화 | B42: 1 | C42: ='응답데이터'!Y36 | D42: ='응답데이터'!Z36
A43: 지역기업 기술흡수역량 강화 | B43: =1/C42 | C43: 1 | D43: ='응답데이터'!AA36
A44: 지역혁신 인재양성 | B44: =1/D42 | C44: =1/D43 | D44: 1
A45: 열 합계 | B45: =SUM(B42:B44) | C45: =SUM(C42:C44) | D45: =SUM(D42:D44)
...

Sheet 종합순위
A1: AHP 종합 가중치 및 우선순위
A3: [제1계층 핵심가치 가중치]
A4: 핵심가치 | B4: 가중치 | C4: 순위 | D4: CR값 | E4: 적합성
A5: 자립성 | B5: ='AHP분석결과'!H17 | C5: =RANK(B5,B$5:B$10) | D5: ='AHP분석결과'!B36 | E5: =IF(D5<=0.1,"적합","부적합")
A6: 연계성 | B6: ='AHP분석결과'!H18 | C6: =RANK(B6,B$5:B$10)
A7: 실용성 | B7: ='AHP분석결과'!H19 | C7: =RANK(B7,B$5:B$10)
A8: 포용성 | B8: ='AHP분석결과'!H20 | C8: =RANK(B8,B$5:B$10)
A9: 지속가능성 | B9: ='AHP분석결과'!H21 | C9: =RANK(B9,B$5:B$10)
A10: 확장성 | B10: ='AHP분석결과'!H22 | C10: =RANK(B10,B$5:B$10)
A12: [종합 가중치 (글로벌 가중치)]
A13: 핵심가치 | B13: 정책요인 | C13: 로컬가중치 | D13: 핵심가치가중치 | E13: 글로벌가중치 | F13: 종합순위 | G13: CR값
A14: 자립성 | B14: 지역 R&D 역량 강화 | C14: ='AHP분석결과'!E49 | D14: =B5 | E14: =C14*D14 | F14: =RANK(E14,E$14:E$31) | G14: ='AHP분석결과'!B62
A15: 자립성 | B15: 지역기업 기술흡수역량 강화 | C15: ='AHP분석결과'!E50 | D15: =B5 | E15: =C15*D15 | F15: =RANK(E15,E$14:E$31)
A16: 자립성 | B16: 지역혁신 인재양성 | C16: ='AHP분석결과'!E51 | D16: =B5 | E16: =C16*D16 | F16: =RANK(E16,E$14:E$31)
A17: 연계성 | B17: 산·학·연·관 협력 강화 | C17: ='AHP분석결과'!E75 | D17: =B6 | E17: =C17*D17 | F17: =RANK(E17,E$14:E$31) | G17: ='AHP분석결과'!B88
A18: 연계성 | B18: 기업 간 네트워크 활성화 | C18: ='AHP분석결과'!E76 | D18: =B6 | E18: =C18*D18 | F18: =RANK(E18,E$14:E$31)
A19: 연계성 | B19: 중간지원기관 조정 기능 강화 | C19: ='AHP분석결과'!E77 | D19: =B6 | E19: =C19*D19 | F19: =RANK(E19,E$14:E$31)
A20: 실용성 | B20: 기술사업화 지원 | C20: ='AHP분석결과'!E101 | D20: =B7 | E20: =C20*D20 | F20: =RANK(E20,E$14:E$31) | G20: ='AHP분석결과'!B114
A21: 실용성 | B21: 기업 기술애로 해결 | C21: ='AHP분석결과'!E102 | D21: =B7 | E21: =C21*D21 | F21: =RANK(E21,E$14:E$31)
A22: 실용성 | B22: 매출·고용 창출 연계 | C22: ='AHP분석결과'!E103 | D22: =B7 | E22: =C22*D22 | F22: =RANK(E22,E$14:E$31)
A23: 포용성 | B23: 중소기업 정책 접근성 강화 | C23: ='AHP분석결과'!E127 | D23: =B8 | E23: =C23*D23 | F23: =RANK(E23,E$14:E$31) | G23: ='AHP분석결과'!B140
A24: 포용성 | B24: 청년·창업기업 참여 확대 | C24: ='AHP분석결과'!E128 | D24: =B8 | E24: =C24*D24 | F24: =RANK(E24,E$14:E$31)
A25: 포용성 | B25: 지역대학 및 지역사회 참여 확대 | C25: ='AHP분석결과'!E129 | D25: =B8 | E25: =C25*D25 | F25: =RANK(E25,E$14:E$31)
A26: 지속가능성 | B26: 정책 연속성 확보 | C26: ='AHP분석결과'!E153 | D26: =B9 | E26: =C26*D26 | F26: =RANK(E26,E$14:E$31) | G26: ='AHP분석결과'!B166
A27: 지속가능성 | B27: 혁신거버넌스 안정화 | C27: ='AHP분석결과'!E154 | D27: =B9 | E27: =C27*D27 | F27: =RANK(E27,E$14:E$31)
A28: 지속가능성 | B28: 혁신인프라 유지·고도화 | C28: ='AHP분석결과'!E155 | D28: =B9 | E28: =C28*D28 | F28: =RANK(E28,E$14:E$31)
A29: 확장성 | B29: 외부 지식·기술 연계 | C29: ='AHP분석결과'!E179 | D29: =B10 | E29: =C29*D29 | F29: =RANK(E29,E$14:E$31) | G29: ='AHP분석결과'!B192
A30: 확장성 | B30: 글로벌 시장 진출 지원 | C30: ='AHP분석결과'!E180 | D30: =B10 | E30: =C30*D30 | F30: =RANK(E30,E$14:E$31)
A31: 확장성 | B31: 신산업 전환 및 확산 | C31: ='AHP분석결과'!E181 | D31: =B10 | E31: =C31*D31 | F31: =RANK(E31,E$14:E$31)

Sheet 차트1_핵심가치막대

Sheet 차트2_핵심가치파이

Sheet 차트3_핵심가치레이더

Sheet 차트4_글로벌가중치

Sheet 차트5_자립성

Sheet 차트6_연계성

Sheet 차트7_실용성

Sheet 차트8_포용성

Sheet 차트9_지속가능성

Sheet 차트10_확장성

Sheet 한계및결론
A1: AHP 분석의 한계 및 결론
A3: 1. 연구 목적 및 의의
A4: 본 연구는 충남 지역혁신체제 구축을 위한 핵심가치(자립성, 연계성, 실용성, 포용성, 지속가능성, 확장성)와
A5: 18개 정책요인의 상대적 중요도 및 우선순위를 AHP(Analytic Hierarchy Process) 기법을 통해 분석하였다.
A6: 이를 통해 지역혁신정책 수립 시 전문가 관점에서의 정책적 우선순위를 실증적으로 도출하고자 하였다.
A8: 2. 분석 방법론
A9: AHP 기법은 Saaty(1980)가 개발한 다기준 의사결정 방법으로, 복잡한 의사결정 문제를 계층화하고
A10: 쌍대비교를 통해 각 요인의 상대적 중요도를 도출한다.
A11: 본 연구는 2계층 구조(제1계층: 6개 핵심가치, 제2계층: 각 3개 정책요인)로 설계하였으며,
A12: 9점 척도를 활용한 쌍대비교를 통해 가중치를 산출하고 일관성 비율(CR<=0.1)을 검증하였다.
A14: [AHP 계산 절차]
A15: Step 1: 전문가 응답을 기하평균으로 통합하여 그룹 쌍대비교행렬(A) 구성
... A80: - 조근태, 조용곤, 강현수 (2003). 앞서가는 리더들의 계층분석적 의사결정. 동현출판사.

Sheet 사용안내
A1: 엑셀 파일 사용 안내
A3: 사용 절차
A4: 1. 온라인 설문지(AHP_설문조사.html)를 응답자에게 배포합니다.
A5: 2. 응답자가 설문 완료 후 CSV 파일을 다운로드합니다.
A6: 3. CSV 파일을 열어 쌍대비교값(9번째 열부터)을 복사합니다.
A7: 4. 본 엑셀의 '응답데이터' 시트 노란색 셀에 붙여넣습니다.
A8: 5. 'AHP분석결과' 시트에서 자동 계산된 결과를 확인합니다.
A9: 6. '종합순위' 시트에서 최종 우선순위를 확인합니다.
A10: 7. '차트분석' 시트에서 시각화 결과를 확인합니다.
A12: 입력값 설명
A13: - 왼쪽 항목이 절대적으로 중요: 9
A14: - 왼쪽 항목이 매우 중요: 7
... A35: - 엑셀 수식이 포함되어 있으므로 셀 서식을 변경하지 마세요.
